<?xml version="1.0" encoding="UTF-8"?>
<robot name="a2d_planning_simplified">
  <joint name="Joint_hand_l" type="fixed">
    <origin xyz="0. 0. 0." rpy="1.5708008 1.5707957 1.5708008"/>
    <parent link="Link7_l"/>
    <child link="left_base_link"/>
  </joint>
  <joint name="Joint_hand_r" type="fixed">
    <origin xyz="-0.0000013 -0.0000014 0.0000002" rpy="0.7888771 1.5707859 0.7888746"/>
    <parent link="Link7_r"/>
    <child link="right_base_link"/>
  </joint>
  <joint name="gripper_center_joint" type="fixed">
    <origin xyz="-0.23 0. 0. " rpy="1.5707964 0. -1.5707964"/>
    <parent link="left_base_link"/>
    <child link="gripper_center"/>
  </joint>
  <joint name="joint_arm_mount" type="fixed">
    <origin xyz="-0.305 -0. 0. " rpy="1.5707927 -0. -1.5707927"/>
    <parent link="link_pitch_body"/>
    <child link="link_arm"/>
  </joint>
  <joint name="joint_body_pitch" type="revolute">
    <origin xyz="0.131 0. 0. " rpy="-1.5871902 1.5707927 -0.0163902"/>
    <parent link="link_up_down_body"/>
    <child link="link_pitch_body"/>
    <axis xyz="0. 0. 1."/>
    <limit lower="0." upper="1.0471976" effort="1000." velocity="2.6099999"/>
  </joint>
  <joint name="joint_head_pitch" type="revolute">
    <origin xyz="0.441 -0. 0. " rpy="1.5707998 0. 1.5708 "/>
    <parent link="link_yaw_head"/>
    <child link="link_pitch_head"/>
    <axis xyz="0. 1. 0."/>
    <limit lower="-1.0471976" upper="1.0471976" effort="10000000." velocity="0."/>
  </joint>
  <joint name="joint_head_yaw" type="continuous">
    <origin xyz="0. 0. 0." rpy="3.1415925 -0.0000001 3.1415927"/>
    <parent link="link_pitch_body"/>
    <child link="link_yaw_head"/>
    <axis xyz="0. 0. 1."/>
  </joint>
  <joint name="joint_left_arm_mount" type="fixed">
    <origin xyz="0.0000001 0.025 0.0000001" rpy="-1.5707963 -0. -0.0000037"/>
    <parent link="link_arm"/>
    <child link="base_link_l"/>
  </joint>
  <joint name="joint_lift_body" type="prismatic">
    <origin xyz="0. 0. 0.6485" rpy="0. 0. 0."/>
    <parent link="base_link"/>
    <child link="link_up_down_body"/>
    <axis xyz="0. 0. 1."/>
    <limit lower="0." upper="0.5" effort="1000." velocity="2.6099999"/>
  </joint>
  <joint name="joint_right_arm_mount" type="fixed">
    <origin xyz="-0.0000001 -0.025 -0.0000001" rpy="-1.5707964 -0.0000025 3.141589 "/>
    <parent link="link_arm"/>
    <child link="base_link_r"/>
  </joint>
  <joint name="left_arm_joint1" type="revolute">
    <origin xyz="-0.0000008 0.0000008 0.188 " rpy="-0.0000037 0.0000037 3.1415927"/>
    <parent link="base_link_l"/>
    <child link="Link1_l"/>
    <axis xyz="0. 0. 1."/>
    <limit lower="-3.1399998" upper="3.1399998" effort="1000." velocity="3.1400001"/>
  </joint>
  <joint name="left_arm_joint2" type="revolute">
    <origin xyz="0. 0. 0." rpy="1.5708 -0.0000004 1.5708 "/>
    <parent link="Link1_l"/>
    <child link="Link2_l"/>
    <axis xyz="0. 0. 1."/>
    <limit lower="-2.3561945" upper="2.3561945" effort="1000." velocity="3.1400001"/>
  </joint>
  <joint name="left_arm_joint3" type="revolute">
    <origin xyz="0.0000001 0.305 -0. " rpy="1.5548222 1.570793 3.1256218"/>
    <parent link="Link2_l"/>
    <child link="Link3_l"/>
    <axis xyz="0. 0. 1."/>
    <limit lower="-3.1399998" upper="3.1399998" effort="1000." velocity="3.1400001"/>
  </joint>
  <joint name="left_arm_joint4" type="revolute">
    <origin xyz="-0. 0. 0.0000002" rpy="1.5708 0. 0.0000003"/>
    <parent link="Link3_l"/>
    <child link="Link4_l"/>
    <axis xyz="0. 0. 1."/>
    <limit lower="-2.3561945" upper="2.3561945" effort="1000." velocity="3.1400001"/>
  </joint>
  <joint name="left_arm_joint5" type="revolute">
    <origin xyz="0. 0.1975 0. " rpy="-1.5707927 0. 0.0000072"/>
    <parent link="Link4_l"/>
    <child link="Link5_l"/>
    <axis xyz="0. 0. 1."/>
    <limit lower="-3.1399998" upper="3.1399998" effort="1000." velocity="3.1400001"/>
  </joint>
  <joint name="left_arm_joint6" type="revolute">
    <origin xyz="-0. 0. 0.0000002" rpy="-1.5707922 -0. 0.0000072"/>
    <parent link="Link5_l"/>
    <child link="Link6_l"/>
    <axis xyz="0. 0. 1."/>
    <limit lower="-2.3561945" upper="2.3561945" effort="1000." velocity="3.1400001"/>
  </joint>
  <joint name="left_arm_joint7" type="revolute">
    <origin xyz="0. -0.181 0.0000001" rpy="1.5707922 -0. 0.0000072"/>
    <parent link="Link6_l"/>
    <child link="Link7_l"/>
    <axis xyz="0. 0. 1."/>
    <limit lower="-6.2799996" upper="6.2799996" effort="1000." velocity="3.1400001"/>
  </joint>
  <joint name="right_arm_joint1" type="revolute">
    <origin xyz="-0.0000008 -0.0000008 0.188 " rpy="0.0000035 0.0000037 -3.1415927"/>
    <parent link="base_link_r"/>
    <child link="Link1_r"/>
    <axis xyz="0. 0. 1."/>
    <limit lower="-3.1399998" upper="3.1399998" effort="1000." velocity="3.1400001"/>
  </joint>
  <joint name="right_arm_joint2" type="revolute">
    <origin xyz="0. 0.0000001 0. " rpy="-1.5708 -0.0000001 1.5708 "/>
    <parent link="Link1_r"/>
    <child link="Link2_r"/>
    <axis xyz="0. 0. 1."/>
    <limit lower="-2.3561945" upper="2.3561945" effort="1000." velocity="3.1400001"/>
  </joint>
  <joint name="right_arm_joint3" type="revolute">
    <origin xyz="-0. -0.305 -0. " rpy="1.5967033 -1.570793 -0.0259034"/>
    <parent link="Link2_r"/>
    <child link="Link3_r"/>
    <axis xyz="0. 0. 1."/>
    <limit lower="-3.1399998" upper="3.1399998" effort="1000." velocity="3.1400001"/>
  </joint>
  <joint name="right_arm_joint4" type="revolute">
    <origin xyz="-0. 0. 0.0000002" rpy="1.5707928 0. -0.0000076"/>
    <parent link="Link3_r"/>
    <child link="Link4_r"/>
    <axis xyz="0. 0. 1."/>
    <limit lower="-2.3561945" upper="2.3561945" effort="1000." velocity="3.1400001"/>
  </joint>
  <joint name="right_arm_joint5" type="revolute">
    <origin xyz="0. 0.1975 0. " rpy="-1.5707927 -0. 0.0000072"/>
    <parent link="Link4_r"/>
    <child link="Link5_r"/>
    <axis xyz="0. 0. 1."/>
    <limit lower="-3.1399998" upper="3.1399998" effort="1000." velocity="3.1400001"/>
  </joint>
  <joint name="right_arm_joint6" type="revolute">
    <origin xyz="-0. 0. -0." rpy="-1.5707927 -0. 0.0000072"/>
    <parent link="Link5_r"/>
    <child link="Link6_r"/>
    <axis xyz="0. 0. 1."/>
    <limit lower="-2.3561945" upper="2.3561945" effort="1000." velocity="3.1400001"/>
  </joint>
  <joint name="right_arm_joint7" type="revolute">
    <origin xyz="0.0000013 -0.181 0.0000013" rpy="1.5707853 -0.0000025 0.0000001"/>
    <parent link="Link6_r"/>
    <child link="Link7_r"/>
    <axis xyz="0. 0. 1."/>
    <limit lower="-3.1399998" upper="3.1399998" effort="1000." velocity="3.1400001"/>
  </joint>
  <joint name="right_gripper_center_joint" type="fixed">
    <origin xyz="-0.227 0. 0. " rpy="1.5707964 0. -1.5707964"/>
    <parent link="right_base_link"/>
    <child link="right_gripper_center"/>
  </joint>
  <joint name="root_joint" type="fixed">
    <origin xyz="0. 0. 0." rpy="0. 0. 0."/>
    <parent link="A2D"/>
    <child link="base_link"/>
  </joint>
  <link name="A2D">
    <visual>
      <origin xyz="0.1139909 1.0185003 0.9535007" rpy="3.1415927 -0.0000216 -3.1415854"/>
      <geometry>
        <mesh filename="file:///home/pm/Desktop/Project/robot_stack/assets/a2d/meshes/left_Left_2_Link_visuals.obj" scale="1. 1. 1."/>
      </geometry>
    </visual>
    <visual>
      <origin xyz="0.163544 1.0029408 0.9534999" rpy="0. 0. 0."/>
      <geometry>
        <mesh filename="file:///home/pm/Desktop/Project/robot_stack/assets/a2d/meshes/left_Right_01_Link_visuals.obj" scale="1. 1. 1."/>
      </geometry>
    </visual>
    <visual>
      <origin xyz="0.183004 1.0158409 0.9534997" rpy="0. 0. 0."/>
      <geometry>
        <mesh filename="file:///home/pm/Desktop/Project/robot_stack/assets/a2d/meshes/left_Right_00_Link_visuals.obj" scale="1. 1. 1."/>
      </geometry>
    </visual>
    <visual>
      <origin xyz="0.1479909 1.0185007 0.9535002" rpy="0. 0. 0."/>
      <geometry>
        <mesh filename="file:///home/pm/Desktop/Project/robot_stack/assets/a2d/meshes/left_Right_2_Link_visuals.obj" scale="1. 1. 1."/>
      </geometry>
    </visual>
    <visual>
      <origin xyz="0.098438 1.0029402 0.9535009" rpy="3.1415927 -0.0000216 -3.1415854"/>
      <geometry>
        <mesh filename="file:///home/pm/Desktop/Project/robot_stack/assets/a2d/meshes/left_Left_01_Link_visuals.obj" scale="1. 1. 1."/>
      </geometry>
    </visual>
    <visual>
      <origin xyz="0.0789779 1.01584 0.9535013" rpy="3.1415927 -0.0000216 -3.1415854"/>
      <geometry>
        <mesh filename="file:///home/pm/Desktop/Project/robot_stack/assets/a2d/meshes/left_Left_00_Link_visuals.obj" scale="1. 1. 1."/>
      </geometry>
    </visual>
    <visual>
      <origin xyz="0.1480029 -1.0185002 0.9535034" rpy="3.1415925 -0.0000047 0.0000146"/>
      <geometry>
        <mesh filename="file:///home/pm/Desktop/Project/robot_stack/assets/a2d/meshes/right_Left_2_Link_visuals.obj" scale="1. 1. 1."/>
      </geometry>
    </visual>
    <visual>
      <origin xyz="0.0984496 -1.0029409 0.9535035" rpy="0.0000075 -0.0000025 -3.141578 "/>
      <geometry>
        <mesh filename="file:///home/pm/Desktop/Project/robot_stack/assets/a2d/meshes/right_Right_01_Link_visuals.obj" scale="1. 1. 1."/>
      </geometry>
    </visual>
    <visual>
      <origin xyz="0.0789898 -1.0158411 0.9535036" rpy="0.0000075 -0.0000025 -3.141578 "/>
      <geometry>
        <mesh filename="file:///home/pm/Desktop/Project/robot_stack/assets/a2d/meshes/right_Right_00_Link_visuals.obj" scale="1. 1. 1."/>
      </geometry>
    </visual>
    <visual>
      <origin xyz="0.1140029 -1.0185007 0.9535035" rpy="0.0000075 -0.0000025 -3.141578 "/>
      <geometry>
        <mesh filename="file:///home/pm/Desktop/Project/robot_stack/assets/a2d/meshes/right_Right_2_Link_visuals.obj" scale="1. 1. 1."/>
      </geometry>
    </visual>
    <visual>
      <origin xyz="0.1635556 -1.0029399 0.9535033" rpy="3.1415925 -0.0000047 0.0000146"/>
      <geometry>
        <mesh filename="file:///home/pm/Desktop/Project/robot_stack/assets/a2d/meshes/right_Left_01_Link_visuals.obj" scale="1. 1. 1."/>
      </geometry>
    </visual>
    <visual>
      <origin xyz="0.1830159 -1.0158397 0.9535034" rpy="3.1415925 -0.0000047 0.0000146"/>
      <geometry>
        <mesh filename="file:///home/pm/Desktop/Project/robot_stack/assets/a2d/meshes/right_Left_00_Link_visuals.obj" scale="1. 1. 1."/>
      </geometry>
    </visual>
    <collision>
      <origin xyz="0.1139909 1.0185003 0.9535007" rpy="3.1415927 -0.0000216 -3.1415854"/>
      <geometry>
        <mesh filename="file:///home/pm/Desktop/Project/robot_stack/assets/a2d/meshes/left_Left_2_Link_collisions.obj" scale="1. 1. 1."/>
      </geometry>
    </collision>
    <collision>
      <origin xyz="0.163544 1.0029408 0.9534999" rpy="0. 0. 0."/>
      <geometry>
        <mesh filename="file:///home/pm/Desktop/Project/robot_stack/assets/a2d/meshes/left_Right_01_Link_collisions.obj" scale="1. 1. 1."/>
      </geometry>
    </collision>
    <collision>
      <origin xyz="0.183004 1.0158409 0.9534997" rpy="0. 0. 0."/>
      <geometry>
        <mesh filename="file:///home/pm/Desktop/Project/robot_stack/assets/a2d/meshes/left_Right_00_Link_collisions.obj" scale="1. 1. 1."/>
      </geometry>
    </collision>
    <collision>
      <origin xyz="0.1479909 1.0185007 0.9535002" rpy="0. 0. 0."/>
      <geometry>
        <mesh filename="file:///home/pm/Desktop/Project/robot_stack/assets/a2d/meshes/left_Right_2_Link_collisions.obj" scale="1. 1. 1."/>
      </geometry>
    </collision>
    <collision>
      <origin xyz="0.098438 1.0029402 0.9535009" rpy="3.1415927 -0.0000216 -3.1415854"/>
      <geometry>
        <mesh filename="file:///home/pm/Desktop/Project/robot_stack/assets/a2d/meshes/left_Left_01_Link_collisions.obj" scale="1. 1. 1."/>
      </geometry>
    </collision>
    <collision>
      <origin xyz="0.0789779 1.01584 0.9535013" rpy="3.1415927 -0.0000216 -3.1415854"/>
      <geometry>
        <mesh filename="file:///home/pm/Desktop/Project/robot_stack/assets/a2d/meshes/left_Left_00_Link_collisions.obj" scale="1. 1. 1."/>
      </geometry>
    </collision>
    <collision>
      <origin xyz="0.1480029 -1.0185002 0.9535034" rpy="3.1415925 -0.0000047 0.0000146"/>
      <geometry>
        <mesh filename="file:///home/pm/Desktop/Project/robot_stack/assets/a2d/meshes/right_Left_2_Link_collisions.obj" scale="1. 1. 1."/>
      </geometry>
    </collision>
    <collision>
      <origin xyz="0.0984496 -1.0029409 0.9535035" rpy="0.0000075 -0.0000025 -3.141578 "/>
      <geometry>
        <mesh filename="file:///home/pm/Desktop/Project/robot_stack/assets/a2d/meshes/right_Right_01_Link_collisions.obj" scale="1. 1. 1."/>
      </geometry>
    </collision>
    <collision>
      <origin xyz="0.0789898 -1.0158411 0.9535036" rpy="0.0000075 -0.0000025 -3.141578 "/>
      <geometry>
        <mesh filename="file:///home/pm/Desktop/Project/robot_stack/assets/a2d/meshes/right_Right_00_Link_collisions.obj" scale="1. 1. 1."/>
      </geometry>
    </collision>
    <collision>
      <origin xyz="0.1140029 -1.0185007 0.9535035" rpy="0.0000075 -0.0000025 -3.141578 "/>
      <geometry>
        <mesh filename="file:///home/pm/Desktop/Project/robot_stack/assets/a2d/meshes/right_Right_2_Link_collisions.obj" scale="1. 1. 1."/>
      </geometry>
    </collision>
    <collision>
      <origin xyz="0.1635556 -1.0029399 0.9535033" rpy="3.1415925 -0.0000047 0.0000146"/>
      <geometry>
        <mesh filename="file:///home/pm/Desktop/Project/robot_stack/assets/a2d/meshes/right_Left_01_Link_collisions.obj" scale="1. 1. 1."/>
      </geometry>
    </collision>
    <collision>
      <origin xyz="0.1830159 -1.0158397 0.9535034" rpy="3.1415925 -0.0000047 0.0000146"/>
      <geometry>
        <mesh filename="file:///home/pm/Desktop/Project/robot_stack/assets/a2d/meshes/right_Left_00_Link_collisions.obj" scale="1. 1. 1."/>
      </geometry>
    </collision>
  </link>
  <link name="Link1_l">
    <inertial>
      <origin xyz="-0.0014596 0.0004948 0.017089 " rpy="0. 0. 0."/>
      <mass value="0.43694"/>
      <inertia ixx="0.0013172" ixy="0.0000093" ixz="0.0000152" iyy="0.0010919" iyz="-0.0004122" izz="0.0006714"/>
    </inertial>
    <visual>
      <origin xyz="0. 0. 0." rpy="3.1415923 0. -3.1415927"/>
      <geometry>
        <mesh filename="file:///home/pm/Desktop/Project/robot_stack/assets/a2d/meshes/Link1_l_visuals.obj" scale="1. 1. 1."/>
      </geometry>
    </visual>
    <collision>
      <origin xyz="0. 0. 0." rpy="3.1415923 0. -3.1415927"/>
      <geometry>
        <mesh filename="file:///home/pm/Desktop/Project/robot_stack/assets/a2d/meshes/Link1_l_collisions.obj" scale="1. 1. 1."/>
      </geometry>
    </collision>
  </link>
  <link name="Link1_r">
    <inertial>
      <origin xyz="0.0013193 0.000161 0.018211 " rpy="0. 0. 0."/>
      <mass value="0.48414"/>
      <inertia ixx="0.0014244" ixy="0.0000024" ixz="-0.0000071" iyy="0.0013551" iyz="0.0002924" izz="0.0005629"/>
    </inertial>
    <visual>
      <origin xyz="0. 0.0000001 0. " rpy="3.1415927 0. 3.1415927"/>
      <geometry>
        <mesh filename="file:///home/pm/Desktop/Project/robot_stack/assets/a2d/meshes/Link1_r_visuals.obj" scale="1. 1. 1."/>
      </geometry>
    </visual>
    <collision>
      <origin xyz="0. 0.0000001 0. " rpy="3.1415927 0. 3.1415927"/>
      <geometry>
        <mesh filename="file:///home/pm/Desktop/Project/robot_stack/assets/a2d/meshes/Link1_r_collisions.obj" scale="1. 1. 1."/>
      </geometry>
    </collision>
  </link>
  <link name="Link2_l">
    <inertial>
      <origin xyz="-0.0004301 0.088101 -0.0065021" rpy="0. 0. 0."/>
      <mass value="0.31992"/>
      <inertia ixx="0.0015103" ixy="-0.0000514" ixz="-0.0000025" iyy="0.0004257" iyz="0.0000023" izz="0.0014781"/>
    </inertial>
    <visual>
      <origin xyz="0. 0. 0." rpy="-3.1415927 0.0000004 3.1415925"/>
      <geometry>
        <mesh filename="file:///home/pm/Desktop/Project/robot_stack/assets/a2d/meshes/Link2_l_visuals.obj" scale="1. 1. 1."/>
      </geometry>
    </visual>
    <collision>
      <origin xyz="0. 0. 0." rpy="-3.1415927 0.0000004 3.1415925"/>
      <geometry>
        <mesh filename="file:///home/pm/Desktop/Project/robot_stack/assets/a2d/meshes/Link2_l_collisions.obj" scale="1. 1. 1."/>
      </geometry>
    </collision>
  </link>
  <link name="Link2_r">
    <inertial>
      <origin xyz="0.0001204 -0.088102 -0.0062668" rpy="0. 0. 0."/>
      <mass value="0.31993"/>
      <inertia ixx="0.0015188" ixy="0.0000579" ixz="0.0000024" iyy="0.0004246" iyz="-0.0000046" izz="0.0014817"/>
    </inertial>
    <visual>
      <origin xyz="0. 0. 0." rpy="3.1415927 0.0000004 3.1415927"/>
      <geometry>
        <mesh filename="file:///home/pm/Desktop/Project/robot_stack/assets/a2d/meshes/Link2_r_visuals.obj" scale="1. 1. 1."/>
      </geometry>
    </visual>
    <collision>
      <origin xyz="0. 0. 0." rpy="3.1415927 0.0000004 3.1415927"/>
      <geometry>
        <mesh filename="file:///home/pm/Desktop/Project/robot_stack/assets/a2d/meshes/Link2_r_collisions.obj" scale="1. 1. 1."/>
      </geometry>
    </collision>
  </link>
  <link name="Link3_l">
    <inertial>
      <origin xyz="0.0002259 0.0010417 0.034985 " rpy="0. 0. 0."/>
      <mass value="0.35545"/>
      <inertia ixx="0.002304" ixy="-0.0000001" ixz="0.0000019" iyy="0.0022403" iyz="0.0002541" izz="0.0004278"/>
    </inertial>
    <visual>
      <origin xyz="-0. 0. 0.0000002" rpy="3.1415927 -0. -3.1415923"/>
      <geometry>
        <mesh filename="file:///home/pm/Desktop/Project/robot_stack/assets/a2d/meshes/Link3_l_visuals.obj" scale="1. 1. 1."/>
      </geometry>
    </visual>
    <collision>
      <origin xyz="-0. 0. 0.0000002" rpy="3.1415927 -0. -3.1415923"/>
      <geometry>
        <mesh filename="file:///home/pm/Desktop/Project/robot_stack/assets/a2d/meshes/Link3_l_collisions.obj" scale="1. 1. 1."/>
      </geometry>
    </collision>
  </link>
  <link name="Link3_r">
    <inertial>
      <origin xyz="-0.0000038 -0.0001255 -0.035846 " rpy="0. 0. 0."/>
      <mass value="0.34932"/>
      <inertia ixx="0.002239" ixy="-0.0000018" ixz="-0.0000157" iyy="0.0021947" iyz="-0.000223" izz="0.0004086"/>
    </inertial>
    <visual>
      <origin xyz="-0. 0. 0.0000002" rpy="0.0000001 0. -0.0000004"/>
      <geometry>
        <mesh filename="file:///home/pm/Desktop/Project/robot_stack/assets/a2d/meshes/Link3_r_visuals.obj" scale="1. 1. 1."/>
      </geometry>
    </visual>
    <collision>
      <origin xyz="-0. 0. 0.0000002" rpy="0.0000001 0. -0.0000004"/>
      <geometry>
        <mesh filename="file:///home/pm/Desktop/Project/robot_stack/assets/a2d/meshes/Link3_r_collisions.obj" scale="1. 1. 1."/>
      </geometry>
    </collision>
  </link>
  <link name="Link4_l">
    <inertial>
      <origin xyz="0.0000022 0.071943 -0.0054645" rpy="0. 0. 0."/>
      <mass value="0.1848"/>
      <inertia ixx="0.0006023" ixy="-0.0000592" ixz="0.0000003" iyy="0.0001994" iyz="-0.0000017" izz="0.0005746"/>
    </inertial>
    <visual>
      <origin xyz="0. 0. 0." rpy="-3.1415927 -0. 3.1415927"/>
      <geometry>
        <mesh filename="file:///home/pm/Desktop/Project/robot_stack/assets/a2d/meshes/Link4_l_visuals.obj" scale="1. 1. 1."/>
      </geometry>
    </visual>
    <collision>
      <origin xyz="0. 0. 0." rpy="-3.1415927 -0. 3.1415927"/>
      <geometry>
        <mesh filename="file:///home/pm/Desktop/Project/robot_stack/assets/a2d/meshes/Link4_l_collisions.obj" scale="1. 1. 1."/>
      </geometry>
    </collision>
  </link>
  <link name="Link4_r">
    <inertial>
      <origin xyz="0.0000019 0.071943 -0.0054646" rpy="0. 0. 0."/>
      <mass value="0.1848"/>
      <inertia ixx="0.0006025" ixy="-0.0000579" ixz="-0.0000006" iyy="0.0002009" iyz="-0.0000007" izz="0.0005717"/>
    </inertial>
    <visual>
      <origin xyz="0. 0. 0." rpy="3.1415925 0. -3.1415927"/>
      <geometry>
        <mesh filename="file:///home/pm/Desktop/Project/robot_stack/assets/a2d/meshes/Link4_r_visuals.obj" scale="1. 1. 1."/>
      </geometry>
    </visual>
    <collision>
      <origin xyz="0. 0. 0." rpy="3.1415925 0. -3.1415927"/>
      <geometry>
        <mesh filename="file:///home/pm/Desktop/Project/robot_stack/assets/a2d/meshes/Link4_r_collisions.obj" scale="1. 1. 1."/>
      </geometry>
    </collision>
  </link>
  <link name="Link5_l">
    <inertial>
      <origin xyz="-0.0000008 -0.0000678 -0.012879 " rpy="0. 0. 0."/>
      <mass value="0.1775"/>
      <inertia ixx="0.0004471" ixy="-0.0000012" ixz="-0.0000031" iyy="0.0004016" iyz="-0.0001066" izz="0.000183"/>
    </inertial>
    <visual>
      <origin xyz="-0. 0. 0.0000002" rpy="0.0000006 0. -0. "/>
      <geometry>
        <mesh filename="file:///home/pm/Desktop/Project/robot_stack/assets/a2d/meshes/Link5_l_visuals.obj" scale="1. 1. 1."/>
      </geometry>
    </visual>
    <collision>
      <origin xyz="-0. 0. 0.0000002" rpy="0.0000006 0. -0. "/>
      <geometry>
        <mesh filename="file:///home/pm/Desktop/Project/robot_stack/assets/a2d/meshes/Link5_l_collisions.obj" scale="1. 1. 1."/>
      </geometry>
    </collision>
  </link>
  <link name="Link5_r">
    <inertial>
      <origin xyz="0.000004 -0.0000678 -0.012877 " rpy="0. 0. 0."/>
      <mass value="0.1775"/>
      <inertia ixx="0.000453" ixy="-0.0000001" ixz="0.0000009" iyy="0.0004458" iyz="0.0000405" izz="0.000146"/>
    </inertial>
    <visual>
      <origin xyz="-0. 0. -0." rpy="0. 0. -0."/>
      <geometry>
        <mesh filename="file:///home/pm/Desktop/Project/robot_stack/assets/a2d/meshes/Link5_r_visuals.obj" scale="1. 1. 1."/>
      </geometry>
    </visual>
    <collision>
      <origin xyz="-0. 0. -0." rpy="0. 0. -0."/>
      <geometry>
        <mesh filename="file:///home/pm/Desktop/Project/robot_stack/assets/a2d/meshes/Link5_r_collisions.obj" scale="1. 1. 1."/>
      </geometry>
    </collision>
  </link>
  <link name="Link6_l">
    <inertial>
      <origin xyz="0.0000023 -0.10227 -0.0029117" rpy="0. 0. 0."/>
      <mass value="0.17825"/>
      <inertia ixx="0.0009079" ixy="0.0000175" ixz="0.000001" iyy="0.0001229" iyz="-0.0000015" izz="0.0008886"/>
    </inertial>
    <visual>
      <origin xyz="0. 0. 0." rpy="-3.141592 0. 3.1415927"/>
      <geometry>
        <mesh filename="file:///home/pm/Desktop/Project/robot_stack/assets/a2d/meshes/Link6_l_visuals.obj" scale="1. 1. 1."/>
      </geometry>
    </visual>
    <collision>
      <origin xyz="0. 0. 0." rpy="-3.141592 0. 3.1415927"/>
      <geometry>
        <mesh filename="file:///home/pm/Desktop/Project/robot_stack/assets/a2d/meshes/Link6_l_collisions.obj" scale="1. 1. 1."/>
      </geometry>
    </collision>
  </link>
  <link name="Link6_r">
    <inertial>
      <origin xyz="-0.0000025 -0.10227 -0.0029098" rpy="0. 0. 0."/>
      <mass value="0.17825"/>
      <inertia ixx="0.0009183" ixy="0.0000112" ixz="0.0000014" iyy="0.0001219" iyz="-0.0000007" izz="0.0008994"/>
    </inertial>
    <visual>
      <origin xyz="0. 0. 0." rpy="-3.1415854 0.0000025 -3.1415854"/>
      <geometry>
        <mesh filename="file:///home/pm/Desktop/Project/robot_stack/assets/a2d/meshes/Link6_r_visuals.obj" scale="1. 1. 1."/>
      </geometry>
    </visual>
    <collision>
      <origin xyz="0. 0. 0." rpy="-3.1415854 0.0000025 -3.1415854"/>
      <geometry>
        <mesh filename="file:///home/pm/Desktop/Project/robot_stack/assets/a2d/meshes/Link6_r_collisions.obj" scale="1. 1. 1."/>
      </geometry>
    </collision>
  </link>
  <link name="Link7_l">
    <inertial>
      <origin xyz="-0.0002563 0.0000091 -0.017205 " rpy="0. 0. 0."/>
      <mass value="0.06158"/>
      <inertia ixx="0.0000244" ixy="-0." ixz="0.0000002" iyy="0.0000255" iyz="-0.0000002" izz="0.0000249"/>
    </inertial>
    <visual>
      <origin xyz="0. 0. 0." rpy="0.0000007 0. -0. "/>
      <geometry>
        <mesh filename="file:///home/pm/Desktop/Project/robot_stack/assets/a2d/meshes/Link7_l_visuals.obj" scale="1. 1. 1."/>
      </geometry>
    </visual>
    <collision>
      <origin xyz="0. 0. 0." rpy="0.0000007 0. -0. "/>
      <geometry>
        <mesh filename="file:///home/pm/Desktop/Project/robot_stack/assets/a2d/meshes/Link7_l_collisions.obj" scale="1. 1. 1."/>
      </geometry>
    </collision>
  </link>
  <link name="Link7_r">
    <inertial>
      <origin xyz="0.0002265 0.0001203 -0.017205 " rpy="0. 0. 0."/>
      <mass value="0.06158"/>
      <inertia ixx="0.0000251" ixy="-0.0000004" ixz="-0.0000002" iyy="0.0000249" iyz="-0.0000003" izz="0.0000246"/>
    </inertial>
    <visual>
      <origin xyz="-0.0000013 -0.0000014 0.0000002" rpy="0.0000074 -0.0000074 -0.0000025"/>
      <geometry>
        <mesh filename="file:///home/pm/Desktop/Project/robot_stack/assets/a2d/meshes/Link7_r_visuals.obj" scale="1. 1. 1."/>
      </geometry>
    </visual>
    <collision>
      <origin xyz="-0.0000013 -0.0000014 0.0000002" rpy="0.0000074 -0.0000074 -0.0000025"/>
      <geometry>
        <mesh filename="file:///home/pm/Desktop/Project/robot_stack/assets/a2d/meshes/Link7_r_collisions.obj" scale="1. 1. 1."/>
      </geometry>
    </collision>
  </link>
  <link name="base_link">
    <inertial>
      <origin xyz="-0.0134487 0.001521 -0.0320077" rpy="0. 0. 0."/>
      <mass value="23.2085381"/>
      <inertia ixx="10.355519" ixy="-0.0176329" ixz="-0.7098761" iyy="10.5322937" iyz="-0.2522417" izz="1.1088706"/>
    </inertial>
    <visual>
      <origin xyz="-0.0146625 -0.0001813 0.2123319" rpy="0. 0. 0."/>
      <geometry>
        <mesh filename="file:///home/pm/Desktop/Project/robot_stack/assets/a2d/meshes/base_link_01.obj" scale="1. 1. 1."/>
      </geometry>
    </visual>
    <collision>
      <origin xyz="-0.0146625 -0.0001813 0.2123319" rpy="0. 0. 0."/>
      <geometry>
        <mesh filename="file:///home/pm/Desktop/Project/robot_stack/assets/a2d/meshes/base_link_01.obj" scale="1. 1. 1."/>
      </geometry>
    </collision>
  </link>
  <link name="base_link_l">
    <inertial>
      <origin xyz="0.0002064 -0.0005749 0.034396 " rpy="0. 0. 0."/>
      <mass value="0.37595"/>
      <inertia ixx="0.0003619" ixy="0.0000062" ixz="-0.0000065" iyy="0.0003597" iyz="0.0000072" izz="0.0003787"/>
    </inertial>
    <visual>
      <origin xyz="-0.0000001 0.0000001 0. " rpy="-0.0000035 -0.0000037 -0. "/>
      <geometry>
        <mesh filename="file:///home/pm/Desktop/Project/robot_stack/assets/a2d/meshes/base_link_l_visuals.obj" scale="1. 1. 1."/>
      </geometry>
    </visual>
    <collision>
      <origin xyz="-0.0000001 0.0000001 0. " rpy="-0.0000035 -0.0000037 -0. "/>
      <geometry>
        <mesh filename="file:///home/pm/Desktop/Project/robot_stack/assets/a2d/meshes/base_link_l_collisions.obj" scale="1. 1. 1."/>
      </geometry>
    </collision>
  </link>
  <link name="base_link_r">
    <inertial>
      <origin xyz="0.0002064 -0.0005749 0.034396 " rpy="0. 0. 0."/>
      <mass value="0.37595"/>
      <inertia ixx="0.0003619" ixy="0.0000062" ixz="-0.0000065" iyy="0.0003597" iyz="0.0000072" izz="0.0003787"/>
    </inertial>
    <visual>
      <origin xyz="-0.0000001 -0.0000001 0. " rpy="0.0000037 -0.0000037 0. "/>
      <geometry>
        <mesh filename="file:///home/pm/Desktop/Project/robot_stack/assets/a2d/meshes/base_link_r_visuals.obj" scale="1. 1. 1."/>
      </geometry>
    </visual>
    <collision>
      <origin xyz="-0.0000001 -0.0000001 0. " rpy="0.0000037 -0.0000037 0. "/>
      <geometry>
        <mesh filename="file:///home/pm/Desktop/Project/robot_stack/assets/a2d/meshes/base_link_r_collisions.obj" scale="1. 1. 1."/>
      </geometry>
    </collision>
  </link>
  <link name="gripper_center">
    <inertial>
      <origin xyz="0. 0. 0." rpy="0. 0. 0."/>
      <mass value="0.000001"/>
      <inertia ixx="0.00001" ixy="0." ixz="0." iyy="0.00001" iyz="0." izz="0.00001"/>
    </inertial>
  </link>
  <link name="left_base_link">
    <inertial>
      <origin xyz="0.0000012 0.0000003 0.0536187" rpy="0. 0. 0."/>
      <mass value="0.4431058"/>
      <inertia ixx="0.0006765" ixy="0." ixz="-0.0000004" iyy="0.000716" iyz="0.000017" izz="0.0003005"/>
    </inertial>
    <visual>
      <origin xyz="0. 0. 0." rpy="0. -1.5707964 0. "/>
      <geometry>
        <mesh filename="file:///home/pm/Desktop/Project/robot_stack/assets/a2d/meshes/left_base_link_visuals.obj" scale="1. 1. 1."/>
      </geometry>
    </visual>
    <visual>
      <origin xyz="-0.0581454 -0.0006757 -0.0003889" rpy="-2.865947 1.554776 -2.862583"/>
      <geometry>
        <mesh filename="file:///home/pm/Desktop/Project/robot_stack/assets/a2d/meshes/World_02_Geometry_tn__j0rhk0xq2jmKon6saP_0____________________405_____27_________26_28_Mesh_17_Mesh_17.obj" scale="1. 1. 1."/>
      </geometry>
    </visual>
    <visual>
      <origin xyz="0.0260925 0.0145586 -0.0258385" rpy="0.1674104 0.0154155 0.0033304"/>
      <geometry>
        <mesh filename="file:///home/pm/Desktop/Project/robot_stack/assets/a2d/meshes/World_02_Geometry_tn__j0rhk0xq2jmKon6saP_0__________________________GB_FASTENER_SCREWS_HSHCS_M4X8_N_1_Chamfer1_2_2_Mesh_0_0_Mesh_0.obj" scale="1. 1. 1."/>
      </geometry>
    </visual>
    <visual>
      <origin xyz="0.0145837 0.0294464 -0.0254799" rpy="0.3102155 -1.554776 0.279014 "/>
      <geometry>
        <mesh filename="file:///home/pm/Desktop/Project/robot_stack/assets/a2d/meshes/World_02_Geometry_tn__j0rhk0xq2jmKon6saP_0__________________________GB_FASTENER_SCREWS_HSHCS_M4X8_N_26_Chamfer1_2_2_Mesh_0_0_Mesh_0.obj" scale="1. 1. 1."/>
      </geometry>
    </visual>
    <visual>
      <origin xyz="0.0269289 -0.0130359 0.0224403" rpy="-2.9741824 0.0154156 0.0033304"/>
      <geometry>
        <mesh filename="file:///home/pm/Desktop/Project/robot_stack/assets/a2d/meshes/World_02_Geometry_tn__j0rhk0xq2jmKon6saP_0__________________________GB_FASTENER_SCREWS_HSHCS_M4X8_N_29_Chamfer1_2_2_Mesh_0_0_Mesh_0.obj" scale="1. 1. 1."/>
      </geometry>
    </visual>
    <visual>
      <origin xyz="0.0155137 -0.0280001 0.0224351" rpy="-0.310215 1.554776 -2.8625782"/>
      <geometry>
        <mesh filename="file:///home/pm/Desktop/Project/robot_stack/assets/a2d/meshes/World_02_Geometry_tn__j0rhk0xq2jmKon6saP_0__________________________GB_FASTENER_SCREWS_HSHCS_M4X8_N_3_Chamfer1_2_2_Mesh_0_0_Mesh_0.obj" scale="1. 1. 1."/>
      </geometry>
    </visual>
    <visual>
      <origin xyz="0.0261872 -0.0132484 -0.0257173" rpy="-0.8797874 0.0154156 0.0033304"/>
      <geometry>
        <mesh filename="file:///home/pm/Desktop/Project/robot_stack/assets/a2d/meshes/World_02_Geometry_tn__j0rhk0xq2jmKon6saP_0__________________________GB_FASTENER_SCREWS_HSHCS_M4X8_N_30_Chamfer1_2_2_Mesh_0_0_Mesh_0.obj" scale="1. 1. 1."/>
      </geometry>
    </visual>
    <visual>
      <origin xyz="0.0153179 0.0296568 0.0221837" rpy="2.8313775 1.554776 -2.8625784"/>
      <geometry>
        <mesh filename="file:///home/pm/Desktop/Project/robot_stack/assets/a2d/meshes/World_02_Geometry_tn__j0rhk0xq2jmKon6saP_0__________________________GB_FASTENER_SCREWS_HSHCS_M4X8_N_31_Chamfer1_2_2_Mesh_0_0_Mesh_0.obj" scale="1. 1. 1."/>
      </geometry>
    </visual>
    <visual>
      <origin xyz="0.0266051 -0.0270456 -0.0015779" rpy="-1.9269849 0.0154156 0.0033304"/>
      <geometry>
        <mesh filename="file:///home/pm/Desktop/Project/robot_stack/assets/a2d/meshes/World_02_Geometry_tn__j0rhk0xq2jmKon6saP_0__________________________GB_FASTENER_SCREWS_HSHCS_M4X8_N_4_Chamfer1_2_2_Mesh_0_0_Mesh_0.obj" scale="1. 1. 1."/>
      </geometry>
    </visual>
    <visual>
      <origin xyz="0.0268343 0.0147711 0.022319 " rpy="2.2618053 0.0154155 0.0033304"/>
      <geometry>
        <mesh filename="file:///home/pm/Desktop/Project/robot_stack/assets/a2d/meshes/World_02_Geometry_tn__j0rhk0xq2jmKon6saP_0__________________________GB_FASTENER_SCREWS_HSHCS_M4X8_N_5_Chamfer1_2_2_Mesh_0_0_Mesh_0.obj" scale="1. 1. 1."/>
      </geometry>
    </visual>
    <visual>
      <origin xyz="0.0147796 -0.0282104 -0.0252285" rpy="-2.8313773 -1.554776 0.2790142"/>
      <geometry>
        <mesh filename="file:///home/pm/Desktop/Project/robot_stack/assets/a2d/meshes/World_02_Geometry_tn__j0rhk0xq2jmKon6saP_0__________________________GB_FASTENER_SCREWS_HSHCS_M4X8_N_6_Chamfer1_2_2_Mesh_0_0_Mesh_0.obj" scale="1. 1. 1."/>
      </geometry>
    </visual>
    <visual>
      <origin xyz="0.0264162 0.0285683 -0.0018204" rpy="1.2146077 0.0154155 0.0033304"/>
      <geometry>
        <mesh filename="file:///home/pm/Desktop/Project/robot_stack/assets/a2d/meshes/World_02_Geometry_tn__j0rhk0xq2jmKon6saP_0__________________________GB_FASTENER_SCREWS_HSHCS_M4X8_N_7_Chamfer1_2_2_Mesh_0_0_Mesh_0.obj" scale="1. 1. 1."/>
      </geometry>
    </visual>
    <visual>
      <origin xyz="-0.0908681 -0.2293533 -0.0702888" rpy="1.8464546 1.5547761 -2.8625703"/>
      <geometry>
        <mesh filename="file:///home/pm/Desktop/Project/robot_stack/assets/a2d/meshes/World_02_Geometry_tn__j0rhk0xq2jmKon6saP_0_CTAG2F120S_0_00_______________________20241106_step_10_NONE_11_Mesh_2_Mesh_2.obj" scale="1. 1. 1."/>
      </geometry>
    </visual>
    <visual>
      <origin xyz="-0.0908681 -0.2293533 -0.0702888" rpy="1.8464546 1.5547761 -2.8625703"/>
      <geometry>
        <mesh filename="file:///home/pm/Desktop/Project/robot_stack/assets/a2d/meshes/World_02_Geometry_tn__j0rhk0xq2jmKon6saP_0_CTAG2F120S_0_00_______________________20241106_step_10_NONE_22_Mesh_13_Mesh_13.obj" scale="1. 1. 1."/>
      </geometry>
    </visual>
    <visual>
      <origin xyz="-0.0889849 -0.0891866 0.0004766" rpy="0.729435 1.554776 -2.8625793"/>
      <geometry>
        <mesh filename="file:///home/pm/Desktop/Project/robot_stack/assets/a2d/meshes/World_02_Geometry_tn__j0rhk0xq2jmKon6saP_0_D405____________________8_NONE_9_Mesh_1_Mesh_1.obj" scale="1. 1. 1."/>
      </geometry>
    </visual>
    <collision>
      <origin xyz="0. 0. 0." rpy="0. -1.5707964 0. "/>
      <geometry>
        <mesh filename="file:///home/pm/Desktop/Project/robot_stack/assets/a2d/meshes/left_base_link_collisions.obj" scale="1. 1. 1."/>
      </geometry>
    </collision>
  </link>
  <link name="link_arm">
    <inertial>
      <origin xyz="0. 0. 0." rpy="0. 0. 0."/>
      <mass value="0.000001"/>
      <inertia ixx="0.00001" ixy="0." ixz="0." iyy="0.00001" iyz="0." izz="0.00001"/>
    </inertial>
  </link>
  <link name="link_pitch_body">
    <inertial>
      <origin xyz="0.1937336 -0.0004842 -0.0012401" rpy="0. 0. 0."/>
      <mass value="7.531992"/>
      <inertia ixx="0.0739258" ixy="0.0012805" ixz="0.0005677" iyy="0.2067063" iyz="0.000164" izz="0.1752354"/>
    </inertial>
    <visual>
      <origin xyz="0.694838 0.6694607 -1.4975532" rpy="-1.5707964 -0.0000036 1.5707927"/>
      <geometry>
        <mesh filename="file:///home/pm/Desktop/Project/robot_stack/assets/a2d/meshes/brep_7.obj" scale="1. 1. 1."/>
      </geometry>
    </visual>
    <visual>
      <origin xyz="0.694838 0.6694607 -1.4975532" rpy="-1.5707964 -0.0000036 1.5707927"/>
      <geometry>
        <mesh filename="file:///home/pm/Desktop/Project/robot_stack/assets/a2d/meshes/brep_1.obj" scale="1. 1. 1."/>
      </geometry>
    </visual>
    <collision>
      <origin xyz="0.694838 0.6694607 -1.4975532" rpy="-1.5707964 -0.0000036 1.5707927"/>
      <geometry>
        <mesh filename="file:///home/pm/Desktop/Project/robot_stack/assets/a2d/meshes/brep_7.obj" scale="1. 1. 1."/>
      </geometry>
    </collision>
    <collision>
      <origin xyz="0.694838 0.6694607 -1.4975532" rpy="-1.5707964 -0.0000036 1.5707927"/>
      <geometry>
        <mesh filename="file:///home/pm/Desktop/Project/robot_stack/assets/a2d/meshes/brep_1.obj" scale="1. 1. 1."/>
      </geometry>
    </collision>
  </link>
  <link name="link_pitch_head">
    <inertial>
      <origin xyz="0.0257009 0.0316254 -0.0000377" rpy="0. 0. 0."/>
      <mass value="0.707064"/>
      <inertia ixx="0.0033726" ixy="0.000082" ixz="0.0000877" iyy="0.0051217" iyz="0.0000443" izz="0.005511"/>
    </inertial>
    <visual>
      <origin xyz="-0.1126653 0.0029271 0.0781931" rpy="1.5697576 0.010059 3.1359973"/>
      <geometry>
        <mesh filename="file:///home/pm/Desktop/Project/robot_stack/assets/a2d/meshes/link_pitch_head_01.obj" scale="1. 1. 1."/>
      </geometry>
    </visual>
    <collision>
      <origin xyz="-0.1126653 0.0029271 0.0781931" rpy="1.5697576 0.010059 3.1359973"/>
      <geometry>
        <mesh filename="file:///home/pm/Desktop/Project/robot_stack/assets/a2d/meshes/link_pitch_head_01.obj" scale="1. 1. 1."/>
      </geometry>
    </collision>
  </link>
  <link name="link_up_down_body">
    <inertial>
      <origin xyz="0.0338352 -0.0024804 0.0008384" rpy="0. 0. 0."/>
      <mass value="3.2627544"/>
      <inertia ixx="0.0224671" ixy="-0.0001243" ixz="-0.0000064" iyy="0.0183247" iyz="0.001368" izz="0.0311316"/>
    </inertial>
    <visual>
      <origin xyz="0. 0. 0." rpy="0. 0. 0."/>
      <geometry>
        <mesh filename="file:///home/pm/Desktop/Project/robot_stack/assets/a2d/meshes/link_up_down_body_visuals.obj" scale="1. 1. 1."/>
      </geometry>
    </visual>
    <collision>
      <origin xyz="0. 0. 0." rpy="0. 0. 0."/>
      <geometry>
        <mesh filename="file:///home/pm/Desktop/Project/robot_stack/assets/a2d/meshes/link_up_down_body_collisions.obj" scale="1. 1. 1."/>
      </geometry>
    </collision>
  </link>
  <link name="link_yaw_head">
    <inertial>
      <origin xyz="0.0446068 0.0024175 0.0528374" rpy="0. 0. 0."/>
      <mass value="0.4143429"/>
      <inertia ixx="0.0004398" ixy="0.0000154" ixz="0.0001793" iyy="0.0030064" iyz="0.0000001" izz="0.0030364"/>
    </inertial>
    <visual>
      <origin xyz="0.441 -0. 0. " rpy="-1.5707998 -0.0000026 -1.5707927"/>
      <geometry>
        <mesh filename="file:///home/pm/Desktop/Project/robot_stack/assets/a2d/meshes/link_yaw_head_visuals.obj" scale="1. 1. 1."/>
      </geometry>
    </visual>
    <collision>
      <origin xyz="0.441 -0. 0. " rpy="-1.5707998 -0.0000026 -1.5707927"/>
      <geometry>
        <mesh filename="file:///home/pm/Desktop/Project/robot_stack/assets/a2d/meshes/link_yaw_head_collisions.obj" scale="1. 1. 1."/>
      </geometry>
    </collision>
  </link>
  <link name="right_base_link">
    <inertial>
      <origin xyz="0.0000012 0.0000003 0.0536187" rpy="0. 0. 0."/>
      <mass value="0.4431058"/>
      <inertia ixx="0.0006765" ixy="0." ixz="-0.0000004" iyy="0.000716" iyz="0.000017" izz="0.0003005"/>
    </inertial>
    <visual>
      <origin xyz="0. 0. 0." rpy="0. -1.5707964 0. "/>
      <geometry>
        <mesh filename="file:///home/pm/Desktop/Project/robot_stack/assets/a2d/meshes/right_base_link_visuals.obj" scale="1. 1. 1."/>
      </geometry>
    </visual>
    <visual>
      <origin xyz="-0.0551761 -0.0006727 -0.001538 " rpy="-2.865056 1.5547644 -2.8616915"/>
      <geometry>
        <mesh filename="file:///home/pm/Desktop/Project/robot_stack/assets/a2d/meshes/World_01_Geometry_tn__j0rhk0xq2jmKon6saP_0____________________405_____27_________26_28_Mesh_17_Mesh_17.obj" scale="1. 1. 1."/>
      </geometry>
    </visual>
    <visual>
      <origin xyz="0.0290616 0.0145612 -0.0269885" rpy="0.1673935 0.0154228 0.0033307"/>
      <geometry>
        <mesh filename="file:///home/pm/Desktop/Project/robot_stack/assets/a2d/meshes/World_01_Geometry_tn__j0rhk0xq2jmKon6saP_0__________________________GB_FASTENER_SCREWS_HSHCS_M4X8_N_1_Chamfer1_2_2_Mesh_0_0_Mesh_0.obj" scale="1. 1. 1."/>
      </geometry>
    </visual>
    <visual>
      <origin xyz="0.0175528 0.029449 -0.0266301" rpy="0.3093243 -1.5547644 0.2799056"/>
      <geometry>
        <mesh filename="file:///home/pm/Desktop/Project/robot_stack/assets/a2d/meshes/World_01_Geometry_tn__j0rhk0xq2jmKon6saP_0__________________________GB_FASTENER_SCREWS_HSHCS_M4X8_N_26_Chamfer1_2_2_Mesh_0_0_Mesh_0.obj" scale="1. 1. 1."/>
      </geometry>
    </visual>
    <visual>
      <origin xyz="0.0298983 -0.0130325 0.0212908" rpy="-2.9741993 0.0154229 0.0033307"/>
      <geometry>
        <mesh filename="file:///home/pm/Desktop/Project/robot_stack/assets/a2d/meshes/World_01_Geometry_tn__j0rhk0xq2jmKon6saP_0__________________________GB_FASTENER_SCREWS_HSHCS_M4X8_N_29_Chamfer1_2_2_Mesh_0_0_Mesh_0.obj" scale="1. 1. 1."/>
      </geometry>
    </visual>
    <visual>
      <origin xyz="0.0184832 -0.0279967 0.0212859" rpy="-0.3093239 1.5547644 -2.8616867"/>
      <geometry>
        <mesh filename="file:///home/pm/Desktop/Project/robot_stack/assets/a2d/meshes/World_01_Geometry_tn__j0rhk0xq2jmKon6saP_0__________________________GB_FASTENER_SCREWS_HSHCS_M4X8_N_3_Chamfer1_2_2_Mesh_0_0_Mesh_0.obj" scale="1. 1. 1."/>
      </geometry>
    </visual>
    <visual>
      <origin xyz="0.0291563 -0.0132457 -0.0268668" rpy="-0.8798043 0.0154229 0.0033307"/>
      <geometry>
        <mesh filename="file:///home/pm/Desktop/Project/robot_stack/assets/a2d/meshes/World_01_Geometry_tn__j0rhk0xq2jmKon6saP_0__________________________GB_FASTENER_SCREWS_HSHCS_M4X8_N_30_Chamfer1_2_2_Mesh_0_0_Mesh_0.obj" scale="1. 1. 1."/>
      </geometry>
    </visual>
    <visual>
      <origin xyz="0.0182873 0.0296602 0.0210335" rpy="2.8322687 1.5547644 -2.8616867"/>
      <geometry>
        <mesh filename="file:///home/pm/Desktop/Project/robot_stack/assets/a2d/meshes/World_01_Geometry_tn__j0rhk0xq2jmKon6saP_0__________________________GB_FASTENER_SCREWS_HSHCS_M4X8_N_31_Chamfer1_2_2_Mesh_0_0_Mesh_0.obj" scale="1. 1. 1."/>
      </geometry>
    </visual>
    <visual>
      <origin xyz="0.0295744 -0.0270426 -0.0027272" rpy="-1.9270018 0.0154228 0.0033307"/>
      <geometry>
        <mesh filename="file:///home/pm/Desktop/Project/robot_stack/assets/a2d/meshes/World_01_Geometry_tn__j0rhk0xq2jmKon6saP_0__________________________GB_FASTENER_SCREWS_HSHCS_M4X8_N_4_Chamfer1_2_2_Mesh_0_0_Mesh_0.obj" scale="1. 1. 1."/>
      </geometry>
    </visual>
    <visual>
      <origin xyz="0.0298037 0.0147745 0.021169 " rpy="2.2617884 0.0154228 0.0033307"/>
      <geometry>
        <mesh filename="file:///home/pm/Desktop/Project/robot_stack/assets/a2d/meshes/World_01_Geometry_tn__j0rhk0xq2jmKon6saP_0__________________________GB_FASTENER_SCREWS_HSHCS_M4X8_N_5_Chamfer1_2_2_Mesh_0_0_Mesh_0.obj" scale="1. 1. 1."/>
      </geometry>
    </visual>
    <visual>
      <origin xyz="0.0177487 -0.0282078 -0.0263777" rpy="-2.8322685 -1.5547644 0.2799058"/>
      <geometry>
        <mesh filename="file:///home/pm/Desktop/Project/robot_stack/assets/a2d/meshes/World_01_Geometry_tn__j0rhk0xq2jmKon6saP_0__________________________GB_FASTENER_SCREWS_HSHCS_M4X8_N_6_Chamfer1_2_2_Mesh_0_0_Mesh_0.obj" scale="1. 1. 1."/>
      </geometry>
    </visual>
    <visual>
      <origin xyz="0.0293855 0.0285713 -0.0029706" rpy="1.2145908 0.0154228 0.0033307"/>
      <geometry>
        <mesh filename="file:///home/pm/Desktop/Project/robot_stack/assets/a2d/meshes/World_01_Geometry_tn__j0rhk0xq2jmKon6saP_0__________________________GB_FASTENER_SCREWS_HSHCS_M4X8_N_7_Chamfer1_2_2_Mesh_0_0_Mesh_0.obj" scale="1. 1. 1."/>
      </geometry>
    </visual>
    <visual>
      <origin xyz="-0.0878992 -0.2293515 -0.0714338" rpy="1.8473458 1.5547644 -2.8616786"/>
      <geometry>
        <mesh filename="file:///home/pm/Desktop/Project/robot_stack/assets/a2d/meshes/World_01_Geometry_tn__j0rhk0xq2jmKon6saP_0_CTAG2F120S_0_00_______________________20241106_step_10_NONE_11_Mesh_2_Mesh_2.obj" scale="1. 1. 1."/>
      </geometry>
    </visual>
    <visual>
      <origin xyz="-0.0878992 -0.2293515 -0.0714338" rpy="1.8473458 1.5547644 -2.8616786"/>
      <geometry>
        <mesh filename="file:///home/pm/Desktop/Project/robot_stack/assets/a2d/meshes/World_01_Geometry_tn__j0rhk0xq2jmKon6saP_0_CTAG2F120S_0_00_______________________20241106_step_10_NONE_22_Mesh_13_Mesh_13.obj" scale="1. 1. 1."/>
      </geometry>
    </visual>
    <visual>
      <origin xyz="-0.0860156 -0.0891836 -0.0006708" rpy="0.7303262 1.5547644 -2.8616877"/>
      <geometry>
        <mesh filename="file:///home/pm/Desktop/Project/robot_stack/assets/a2d/meshes/World_01_Geometry_tn__j0rhk0xq2jmKon6saP_0_D405____________________8_NONE_9_Mesh_1_Mesh_1.obj" scale="1. 1. 1."/>
      </geometry>
    </visual>
    <collision>
      <origin xyz="0. 0. 0." rpy="0. -1.5707964 0. "/>
      <geometry>
        <mesh filename="file:///home/pm/Desktop/Project/robot_stack/assets/a2d/meshes/right_base_link_collisions.obj" scale="1. 1. 1."/>
      </geometry>
    </collision>
  </link>
  <link name="right_gripper_center">
    <inertial>
      <origin xyz="0. 0. 0." rpy="0. 0. 0."/>
      <mass value="0.000001"/>
      <inertia ixx="0.00001" ixy="0." ixz="0." iyy="0.00001" iyz="0." izz="0.00001"/>
    </inertial>
  </link>
</robot>
